Workbook

Sheet README
A1: 엠플랜잇 랜딩 레퍼런스 리서치 — 캡처 큐 & 평가 시트
A2: Upstream: 기획/10_디자이너_레퍼런스리서치_브리프.md · Issued 2026-04-24 · Deadline 2026-04-28(월) 17:00
A4: 1. 업무 개요
A5: • 목적: 엠플랜잇 GA 랜딩플랫폼의 섹션 컴포넌트 라이브러리 v2 입력을 만들기 위한 시장 실증 패턴 수집. • 산출물: Figma 보드 1장 (16 섹션 × 3~5 variant, 총 약 60개 캡처, 최소 15개 브랜드). • 본 엑셀의 역할: 진척 추적, 4문항 루브릭 기반 평가, 중복 variant 방지, 품질 16체크 자동화.
A7: 2. 레퍼런스 채택 기준 — 4문항 루브릭 (브리프 §4.1)
A8: 각 캡처는 아래 4문항에 Y/N으로 답한다. Y 개수로 ★ 등급이 정해진다. 애매하면 N.
A10: # | B10: 문항 | C10: YES 조건 | D10: NO 조건 | E10: 근거 예시 | F10: 칼럼명
A11: Q1 | B11: GA 적합도 | C11: 보험 GA·중개·상담 연결 목적·신뢰·전문형 톤·전환 흐름 일치 | D11: 톤·CTA·전환 구조가 GA와 어긋남 (예: 구매 플로우만 있음) | E11: 리드폼 중심, 신뢰 데이터, 상담 연결 CTA 존재 | F11: y_ga
A12: Q2 | B12: 변형 축 독창성 | C12: 이미 수집된 다른 variant 와 확실히 다른 패턴 | D12: 같은 variant axis 로 이미 1건 있음 | E12: 오른쪽 sticky가 있는데 또 오른쪽 sticky = NO | F12: y_origin
A13: Q3 | B13: UX·비주얼 완성도 | C13: 반응형 안정 · 접근성 기본 · 정보 위계 명확 · 깨짐/오타/괴리 없음 | D13: 어느 하나라도 깨짐, 모바일 조잡, 오타/잘못된 정렬 | E13: 모바일 레이아웃 깨짐 없음, 텍스트 위계 명확 | F13: y_polish
A14: Q4 | B14: 재현 가능성 | C14: 우리 스택(정적 HTML + CSS Vars + Pretendard + Lucide + Formspree)으로 합리적 비용 내 재현 | D14: 특수 SDK/결제 통합/고비용 애니메이션 필수 | E14: 정적 HTML·CSS로 복제 가능한 레이아웃·폼 | F14: y_feasible
A16: Y 개수 | B16: 등급 | C16: 정의·조치
A17: 4 / 4 | B17: ★★★★★ | C17: 즉시 v2 라이브러리 채택 권고. 그대로 variant 템플릿 후보.
A18: 3 / 4 | B18: ★★★★ | C18: 조건부 채택. 부족 1곳이 수정·대체 가능한 경우. [이유]에 수정 포인트 명기.
A19: 2 / 4 | B19: ★★★ | C19: 참고·학습 수준. v2 후반·v3 재검토. 지금은 채택 보류.
A20: 1 / 4 | B20: ★★ | C20: 단편 요소(컬러·타이포·미세 UX)만 참고. 프레임 자체는 비채택.
A21: 0 / 4 또는 다크패턴/허위/저작권 | B21: ★ | C21: 기록 보존용 제외 대상. reject_reason 필수 기재.
A23: ※ ★★★★★ 가 전체의 30% 를 넘으면 평가 기준이 느슨한 것. PM 재검수 요청 대상. ※ 같은 브랜드의 같은 variant 가 이미 있으면 2번째는 자동 ★★ 이하로 하향 (Q2 자동 NO). ※ ★ 항목은 반드시 reject_reason 중 하나 기재: darkpattern / copyright / legal / obsolete / unverified_claim / other
A25: 3. 채택안 분류 (adopted)
A26: 값 | B26: 의미 | C26: 조건
A27: Yes | B27: v2 라이브러리 직행 후보 | C27: ★★★★★ 또는 ★★★★ 중 수정 포인트 확정
A28: 조건부 | B28: PM 협의 후 결정 | C28: ★★★★ 이면서 수정 포인트 존재 · 법무/저작권 검토 필요
A29: No | B29: 제외 | C29: ★★★ 이하 또는 하드 NO (다크패턴 등)
A32: 4. Hard NOs (브리프 §7)
A33: • 카피캣 금지: 픽셀 단위 복제·레이아웃 그대로 베끼기는 저작권·상표권 위반 소지. 구조·패턴 참고만.
A34: • 실제 브랜드 로고 사용 금지: 보드에는 스크린샷으로만 존재. v1.0 구현에 실 로고 이식 금지.
A35: • 다크패턴 참고 제외: 'X 버튼 숨김', '취소 버튼 색상 약화' 등은 darkpattern 태그로 제외 권고.
A36: • 저작권 이미지 저장 금지: 고객 후기·상담사 사진은 캡처 시 모자이크 필수.
A37: • 확인되지 않은 주장 포함 금지: '업계 1위'·'만족도 N%' 수치는 출처 없으면 unverified_claim 태그.
A39: 5. 시트 안내
A40: 시트 | B40: 용도 | C40: 핵심 열/기능
A41: Brands | B41: 18개 대상 브랜드 리스트 | C41: 군(A/B/C) · 우선순위(★) · URL · 캡처 가능 여부
A42: Sections | B42: 16개 섹션 라이브러리 | C42: 섹션명 · 변형 축 · 수집 목표 · 필수 태그
A43: Tags | B43: 태그 enum 사전 | C43: 섹션별 허용 enum 값 (오타 방지)
A44: Queue | B44: 브랜드 × 섹션 18×16 매트릭스 | C44: 셀 값: - / todo / done / skip(이유)
A45: Captures | B45: 수집 로그 (행당 1 variant) | C45: 루브릭 Y/N → ★ 자동 · adopted · reject_reason
A46: QA | B46: 자동 집계·경고 | C46: 섹션별 진척 · ★★★★★ 비율 · 중복 variant · 16체크

Sheet Brands
A1: Brands — 대상 브랜드 18개사
A2: A군 GA/비교 8 + B군 직영 7 + C군 핀테크 3 · 캡처 불가 시 대체 후보 컬럼의 브랜드로 대체 후 PM 승인
A4: # | B4: 군 | C4: 우선 | D4: 브랜드 | E4: 도메인 | F4: URL | G4: 주요 섹션 힌트 | H4: 캡처 리스크 | I4: 대체 후보
A5: 1 | B5: A | C5: ★★★ | D5: 키움에셋플래너 | E5: kiwoomasset.com | F5: https://www.kiwoomasset.com | G5: Hero, 리드폼(right_sticky), 수치카드, 상품카드, FAQ, Footer | H5: 낮음 (03 벤치마킹 커버) | I5: -
A6: 2 | B6: A | C6: ★★★ | D6: 메타리치 | E6: metarich.co.kr | F6: https://www.metarich.co.kr | G6: Hero, 로고월(생·손 분리), 상담사, 상품카드, Footer | H6: 낮음 (03 벤치마킹 커버) | I6: -
A7: 3 | B7: A | C7: ★★★ | D7: 굿리치 | E7: goodrich.co.kr | F7: https://goodrich.co.kr | G7: Hero, 리드폼, 수치카드, 상품카드, FAQ | H7: 중간 (앱 유도 강할 수 있음) | I7: 보험365
A8: 4 | B8: A | C8: ★★★ | D8: 보험다모아 | E8: e-insmarket.or.kr | F8: https://e-insmarket.or.kr | G8: 비교 카드, FAQ, Footer (공식 비교) | H8: 중간 (공공 UI, 간헐 캐시) | I8: 공시실
A9: 5 | B9: A | C9: ★★★ | D9: 내보험찾아줌 | E9: cont.credit4u.or.kr | F9: https://cont.credit4u.or.kr | G9: Hero, 단계 프로세스, FAQ, Footer (공공) | H9: 중간 (약관 동의 게이트) | I9: cmap.koica
A10: 6 | B10: A | C10: ★★★ | D10: 보맵 | E10: bomapp.co.kr | F10: https://bomapp.co.kr | G10: Hero, 상품카드, Sticky CTA, Footer | H10: 중간 (앱 랜딩 위주) | I10: 굿보험
A11: 7 | B11: A | C11: ★★★ | D11: 보험플러스 | E11: insuplus.co.kr | F11: https://www.insuplus.co.kr | G11: Hero, 리드폼, 상담사, 상품카드 | H11: 낮음 | I11: -
A12: 8 | B12: A | C12: ★★★ | D12: 토스인슈어런스 | E12: toss.im/insurance | F12: https://toss.im/insurance | G12: Hero, 리드폼, 상품카드, FAQ, Sticky CTA (모바일 퍼스트) | H12: 중간 (모바일 우선, SPA) | I12: tossinsurance
A13: 9 | B13: B | C13: ★★ | D13: 삼성화재 다이렉트 | E13: direct.samsungfire.com | F13: https://direct.samsungfire.com | G13: Hero-as-form, 수치카드, 후기, Sticky CTA, Footer | H13: 낮음 | I13: -
A14: 10 | B14: B | C14: ★★ | D14: DB손해보험 | E14: idbins.com | F14: https://www.idbins.com | G14: Hero, 리드폼, 수치카드, 상품카드, Footer | H14: 낮음 | I14: -
A15: 11 | B15: B | C15: ★★ | D15: 현대해상 다이렉트 | E15: direct.hi.co.kr | F15: https://direct.hi.co.kr | G15: Hero, 리드폼(wizard), 상품카드, FAQ | H15: 낮음 | I15: -
A16: 12 | B16: B | C16: ★★ | D16: 메리츠화재 다이렉트 | E16: direct.meritzfire.com | F16: https://direct.meritzfire.com | G16: Hero, 리드폼, 상품카드, 통계차트 | H16: 낮음 | I16: -
... A22: 18 | B22: C | C22: ★ | D22: 뱅크샐러드 | E22: banksalad.com | F22: https://banksalad.com | G22: Hero, 통계차트, 상품카드, 페르소나 카드 | H22: 낮음 | I22: -

Sheet Sections
A1: Sections — 16 섹션 라이브러리 목표
A2: 각 섹션은 서로 다른 variant axis 로 3~5개 수집. 같은 axis 반복 금지 (브리프 §3 + §4.1 Q2).
A4: § | B4: 섹션 이름 | C4: 변형 축 (Variant Axis) | D4: 수집 목표 | E4: 필수 태그 키 | F4: 중요도
A5: 1 | B5: GNB / 네비게이션 | C5: (a) 드롭다운 유/무 (b) sticky 투명 vs 솔리드 (c) 검색창 | D5: 3~4 | E5: menu_depth, sticky, cta_count, logo_position | F5: 기본
A6: 2 | B6: Hero — 메인 카피 + 시각 | C6: (a) Split vs Full-bleed (b) 실사/일러/Lottie (c) 그라/단색/비디오 | D6: 4~5 | E6: layout, visual, cta_count, headline_lines | F6: 중요
A7: 3 | B7: 리드폼 — Hero 인접형 | C7: (a) right_sticky (b) as_hero (c) inline (d) modal (e) wizard | D7: 5 | E7: position, field_count, consent_ui, cta_label | F7: 최우선 ★★★
A8: 4 | B8: 리드폼 — 본문 중단형 | C8: (a) dark (b) 그라데이션 (c) inverse / 긴 vs 미니멀 | D8: 3 | E8: tone, field_count, cta_label | F8: 중요
A9: 5 | B9: Why Us / Trust Metrics | C9: (a) 2×2 vs 4열 (b) 아이콘 유무 (c) 배경 틴트 | D9: 3~4 | E9: count, icon, bg | F9: 중요
A10: 6 | B10: 상품 안내 카드 그리드 | C10: (a) 2/3/4열 (b) 카드 균일/가변 (c) 링크 1/다수 (d) 아이콘 스타일 | D10: 3~4 | E10: columns, icon_style, card_height | F10: 중요
A11: 7 | B11: 협력사 로고월 | C11: (a) 생·손 분리 (b) 단일 그리드 (c) 컨베이어 (d) 그레이/컬러 | D11: 3~4 | E11: layout, filter, count | F11: 기본
A12: 8 | B12: 절차 프로세스 (Step Flow) | C12: (a) 3 vs 5단계 (b) 가로 vs 세로 (c) 원형 번호 vs 카드 (d) 아이콘 | D12: 3~4 | E12: steps, orient, marker | F12: 기본
A13: 9 | B13: 상담사·전문가 소개 | C13: (a) 슬라이더 vs 그리드 (b) 사진 스타일 (c) bullet 수 | D13: 2~3 | E13: style, photo_type, bullet_count | F13: 선택
A14: 10 | B14: 데이터 교육·통계 섹션 | C14: (a) 정적 SVG (b) 인터랙티브 (c) 다이어그램 (d) dark vs light | D14: 3 | E14: chart_type, interactive, bg | F14: 중요
A15: 11 | B15: 상품 비교 카드 (3~5 보험사) | C15: (a) 가격 공개 vs 마스킹 vs '상담 안내' (b) 3 vs 5 카드 (c) 특약수 | D15: 3 | E15: price_reveal, card_count, feature_count | F15: 중요 (법무)
A16: 12 | B16: 추천 대상 페르소나 카드 | C16: (a) 일러스트/사진/아이콘 (b) 3/4/5+ 카드 (c) 상황 vs 연령 | D16: 2~3 | E16: count, visual, axis | F16: 기본
... A20: 16 | B20: Footer — 준법·사업자 | C20: (a) Variant A/B/C (04 참조) (b) dark vs light (c) 사업자 블록 수 | D20: 3~4 | E20: variant, bg, sns_links | F20: 필수 (법무)

Sheet Tags
A1: Tags — 태그 enum 사전
A2: Captures 시트의 tags 컬럼에 key=value 형식으로 기재. 오타·임의 값 금지.
A4: 섹션 | B4: 태그 키 | C4: 허용 enum 값
A5: §1 GNB | B5: sticky | C5: y / n
A6: §1 GNB | B6: cta_count | C6: 0 / 1 / 2
A7: §1 GNB | B7: logo_position | C7: left / center
A8: §1 GNB | B8: menu_depth | C8: 1 / 2 / 3
A9: §2 Hero | B9: layout | C9: split / full / stacked
A10: §2 Hero | B10: visual | C10: photo / illust / lottie / none
A11: §2 Hero | B11: headline_lines | C11: 1 / 2 / 3
A12: §3 리드폼(인접) | B12: position | C12: right_sticky / as_hero / inline / modal / wizard
A13: §3 리드폼(인접) | B13: consent_ui | C13: inline / accordion / modal
A14: §3 리드폼(인접) | B14: field_count | C14: 3 / 4 / 5 / 6+
A15: §4 리드폼(중단) | B15: tone | C15: dark / brand / light
... A50: 전역 (거부 사유) | B50: reject_reason | C50: darkpattern / copyright / legal / obsolete / unverified_claim / other

Sheet Queue
A1: Queue — 브랜드 × 섹션 캡처 매트릭스
A2: 각 셀에 상태 입력: - (무시) / todo (예정) / done (완료) / skip: 이유 · 'done' 되면 Captures 시트에 행 추가
A4: # | B4: 군 | C4: 브랜드 | D4: §1 GNB | E4: §2 Hero | F4: §3 리드폼(인접) | G4: §4 리드폼(중단) | H4: §5 수치카드 | I4: §6 상품카드 | J4: §7 로고월 | K4: §8 스텝 | L4: §9 상담사 | M4: §10 통계 | N4: §11 비교카드 | O4: §12 페르소나 | P4: §13 FAQ | Q4: §14 후기 | R4: §15 StickyCTA | S4: §16 Footer | T4: 진척 | U4: 목표
A5: 1 | B5: A | C5: 키움에셋플래너 | D5: todo | E5: todo | F5: todo | G5: - | H5: todo | I5: todo | J5: todo | K5: - | L5: - | M5: - | N5: - | O5: - | P5: todo | Q5: - | R5: - | S5: todo | T5: =COUNTIF(D5:S5,"done") -> 0 | U5: =COUNTIF(D5:S5,"todo")+COUNTIF(D5:S5,"done") -> 8
A6: 2 | B6: A | C6: 메타리치 | D6: todo | E6: todo | F6: todo | G6: - | H6: todo | I6: todo | J6: todo | K6: - | L6: - | M6: - | N6: - | O6: - | P6: todo | Q6: - | R6: - | S6: todo | T6: =COUNTIF(D6:S6,"done") -> 0 | U6: =COUNTIF(D6:S6,"todo")+COUNTIF(D6:S6,"done") -> 8
A7: 3 | B7: A | C7: 굿리치 | D7: todo | E7: todo | F7: todo | G7: - | H7: todo | I7: todo | J7: todo | K7: - | L7: - | M7: - | N7: - | O7: - | P7: todo | Q7: - | R7: - | S7: todo | T7: =COUNTIF(D7:S7,"done") -> 0 | U7: =COUNTIF(D7:S7,"todo")+COUNTIF(D7:S7,"done") -> 8
A8: 4 | B8: A | C8: 보험다모아 | D8: todo | E8: todo | F8: todo | G8: - | H8: todo | I8: todo | J8: todo | K8: - | L8: - | M8: - | N8: - | O8: - | P8: todo | Q8: - | R8: - | S8: todo | T8: =COUNTIF(D8:S8,"done") -> 0 | U8: =COUNTIF(D8:S8,"todo")+COUNTIF(D8:S8,"done") -> 8
A9: 5 | B9: A | C9: 내보험찾아줌 | D9: todo | E9: todo | F9: todo | G9: - | H9: todo | I9: todo | J9: todo | K9: - | L9: - | M9: - | N9: - | O9: - | P9: todo | Q9: - | R9: - | S9: todo | T9: =COUNTIF(D9:S9,"done") -> 0 | U9: =COUNTIF(D9:S9,"todo")+COUNTIF(D9:S9,"done") -> 8
A10: 6 | B10: A | C10: 보맵 | D10: todo | E10: todo | F10: todo | G10: - | H10: todo | I10: todo | J10: todo | K10: - | L10: - | M10: - | N10: - | O10: - | P10: todo | Q10: - | R10: - | S10: todo | T10: =COUNTIF(D10:S10,"done") -> 0 | U10: =COUNTIF(D10:S10,"todo")+COUNTIF(D10:S10,"done") -> 8
A11: 7 | B11: A | C11: 보험플러스 | D11: todo | E11: todo | F11: todo | G11: - | H11: todo | I11: todo | J11: todo | K11: - | L11: - | M11: - | N11: - | O11: - | P11: todo | Q11: - | R11: - | S11: todo | T11: =COUNTIF(D11:S11,"done") -> 0 | U11: =COUNTIF(D11:S11,"todo")+COUNTIF(D11:S11,"done") -> 8
A12: 8 | B12: A | C12: 토스인슈어런스 | D12: todo | E12: todo | F12: todo | G12: - | H12: todo | I12: todo | J12: todo | K12: - | L12: - | M12: - | N12: - | O12: - | P12: todo | Q12: - | R12: - | S12: todo | T12: =COUNTIF(D12:S12,"done") -> 0 | U12: =COUNTIF(D12:S12,"todo")+COUNTIF(D12:S12,"done") -> 8
A13: 9 | B13: B | C13: 삼성화재 다이렉트 | D13: - | E13: - | F13: todo | G13: - | H13: todo | I13: todo | J13: - | K13: todo | L13: - | M13: - | N13: - | O13: - | P13: todo | Q13: todo | R13: todo | S13: todo | T13: =COUNTIF(D13:S13,"done") -> 0 | U13: =COUNTIF(D13:S13,"todo")+COUNTIF(D13:S13,"done") -> 8
A14: 10 | B14: B | C14: DB손해보험 | D14: - | E14: - | F14: todo | G14: - | H14: todo | I14: todo | J14: - | K14: todo | L14: - | M14: - | N14: - | O14: - | P14: todo | Q14: todo | R14: - | S14: todo | T14: =COUNTIF(D14:S14,"done") -> 0 | U14: =COUNTIF(D14:S14,"todo")+COUNTIF(D14:S14,"done") -> 7
A15: 11 | B15: B | C15: 현대해상 다이렉트 | D15: - | E15: - | F15: todo | G15: - | H15: todo | I15: todo | J15: - | K15: todo | L15: - | M15: - | N15: - | O15: - | P15: todo | Q15: todo | R15: - | S15: todo | T15: =COUNTIF(D15:S15,"done") -> 0 | U15: =COUNTIF(D15:S15,"todo")+COUNTIF(D15:S15,"done") -> 7
A16: 12 | B16: B | C16: 메리츠화재 다이렉트 | D16: - | E16: - | F16: todo | G16: - | H16: todo | I16: todo | J16: - | K16: todo | L16: - | M16: - | N16: - | O16: - | P16: todo | Q16: todo | R16: - | S16: todo | T16: =COUNTIF(D16:S16,"done") -> 0 | U16: =COUNTIF(D16:S16,"todo")+COUNTIF(D16:S16,"done") -> 7
... A22: 18 | B22: C | C22: 뱅크샐러드 | D22: - | E22: todo | F22: - | G22: - | H22: - | I22: - | J22: - | K22: - | L22: - | M22: todo | N22: - | O22: todo | P22: - | Q22: - | R22: todo | S22: - | T22: =COUNTIF(D22:S22,"done") -> 0 | U22: =COUNTIF(D22:S22,"todo")+COUNTIF(D22:S22,"done") -> 4
A23: 합계 | D23: =COUNTIF(D5:D22,"done") -> 0 | E23: =COUNTIF(E5:E22,"done") -> 0 | F23: =COUNTIF(F5:F22,"done") -> 0 | G23: =COUNTIF(G5:G22,"done") -> 0 | H23: =COUNTIF(H5:H22,"done") -> 0 | I23: =COUNTIF(I5:I22,"done") -> 0 | J23: =COUNTIF(J5:J22,"done") -> 0 | K23: =COUNTIF(K5:K22,"done") -> 0 | ... S23: =COUNTIF(S5:S22,"done") -> 0 | T23: =SUM(T5:T22) -> 0 | U23: =SUM(U5:U22) -> 126
A24: 섹션 최소 목표 | D24: 3 | E24: 4 | F24: 5 | G24: 3 | H24: 3 | I24: 3 | J24: 3 | K24: 3 | L24: 2 | M24: 3 | N24: 3 | O24: 2 | P24: 3 | Q24: 2 | R24: 3 | S24: 3

Sheet Captures
A1: Captures — 레퍼런스 수집 로그
A2: 캡처 1건 = 1행. 루브릭 Y/N 4문항을 TRUE/FALSE 또는 1/0 으로 입력 → ★ 자동 산출. stars·y_sum 은 수식.
A4: id | B4: date | C4: brand | D4: section | E4: variant | F4: url | G4: tags | H4: note | I4: y_ga | J4: y_origin | K4: y_polish | L4: y_feasible | M4: y_sum | N4: stars | O4: adopted | P4: reject_reason | Q4: reason
A5: R001 | M5: =IF(COUNTA(I5:L5)=0,"",N(I5)+N(J5)+N(K5)+N(L5)) | N5: =IF(M5="","",CHOOSE(M5+1,"★","★★","★★★","★★★★","★★★★★"))
A6: R002 | M6: =IF(COUNTA(I6:L6)=0,"",N(I6)+N(J6)+N(K6)+N(L6)) | N6: =IF(M6="","",CHOOSE(M6+1,"★","★★","★★★","★★★★","★★★★★"))
A7: R003 | M7: =IF(COUNTA(I7:L7)=0,"",N(I7)+N(J7)+N(K7)+N(L7)) | N7: =IF(M7="","",CHOOSE(M7+1,"★","★★","★★★","★★★★","★★★★★"))
A8: R004 | M8: =IF(COUNTA(I8:L8)=0,"",N(I8)+N(J8)+N(K8)+N(L8)) | N8: =IF(M8="","",CHOOSE(M8+1,"★","★★","★★★","★★★★","★★★★★"))
A9: R005 | M9: =IF(COUNTA(I9:L9)=0,"",N(I9)+N(J9)+N(K9)+N(L9)) | N9: =IF(M9="","",CHOOSE(M9+1,"★","★★","★★★","★★★★","★★★★★"))
A10: R006 | M10: =IF(COUNTA(I10:L10)=0,"",N(I10)+N(J10)+N(K10)+N(L10)) | N10: =IF(M10="","",CHOOSE(M10+1,"★","★★","★★★","★★★★","★★★★★"))
A11: R007 | M11: =IF(COUNTA(I11:L11)=0,"",N(I11)+N(J11)+N(K11)+N(L11)) | N11: =IF(M11="","",CHOOSE(M11+1,"★","★★","★★★","★★★★","★★★★★"))
A12: R008 | M12: =IF(COUNTA(I12:L12)=0,"",N(I12)+N(J12)+N(K12)+N(L12)) | N12: =IF(M12="","",CHOOSE(M12+1,"★","★★","★★★","★★★★","★★★★★"))
A13: R009 | M13: =IF(COUNTA(I13:L13)=0,"",N(I13)+N(J13)+N(K13)+N(L13)) | N13: =IF(M13="","",CHOOSE(M13+1,"★","★★","★★★","★★★★","★★★★★"))
A14: R010 | M14: =IF(COUNTA(I14:L14)=0,"",N(I14)+N(J14)+N(K14)+N(L14)) | N14: =IF(M14="","",CHOOSE(M14+1,"★","★★","★★★","★★★★","★★★★★"))
A15: R011 | M15: =IF(COUNTA(I15:L15)=0,"",N(I15)+N(J15)+N(K15)+N(L15)) | N15: =IF(M15="","",CHOOSE(M15+1,"★","★★","★★★","★★★★","★★★★★"))
A16: R012 | M16: =IF(COUNTA(I16:L16)=0,"",N(I16)+N(J16)+N(K16)+N(L16)) | N16: =IF(M16="","",CHOOSE(M16+1,"★","★★","★★★","★★★★","★★★★★"))
... A64: R060 | M64: =IF(COUNTA(I64:L64)=0,"",N(I64)+N(J64)+N(K64)+N(L64)) | N64: =IF(M64="","",CHOOSE(M64+1,"★","★★","★★★","★★★★","★★★★★"))

Sheet QA
A1: QA — 자동 집계·경고·품질 16체크
A2: 모든 값은 Captures 시트의 수식 결과. 빈 행이 많으면 0으로 집계.
A4: A. 섹션별 진척 (목표 대비)
A5: 섹션 | B5: 이름 | C5: 현재 건수 | D5: 최소 목표 | E5: 최대 목표 | F5: 상태
A6: §1 | B6: GNB | C6: =COUNTIF(Captures!D:D,"§1") -> 0 | D6: 3 | E6: 4 | F6: =IF(C6=0,"미착수",IF(C6<D6,"부족 "&(D6-C6)&"건",IF(C6<=E6,"OK","초과"))) -> 미착수
A7: §2 | B7: Hero | C7: =COUNTIF(Captures!D:D,"§2") -> 0 | D7: 4 | E7: 5 | F7: =IF(C7=0,"미착수",IF(C7<D7,"부족 "&(D7-C7)&"건",IF(C7<=E7,"OK","초과"))) -> 미착수
A8: §3 | B8: 리드폼(인접) | C8: =COUNTIF(Captures!D:D,"§3") -> 0 | D8: 5 | E8: 5 | F8: =IF(C8=0,"미착수",IF(C8<D8,"부족 "&(D8-C8)&"건",IF(C8<=E8,"OK","초과"))) -> 미착수
A9: §4 | B9: 리드폼(중단) | C9: =COUNTIF(Captures!D:D,"§4") -> 0 | D9: 3 | E9: 3 | F9: =IF(C9=0,"미착수",IF(C9<D9,"부족 "&(D9-C9)&"건",IF(C9<=E9,"OK","초과"))) -> 미착수
A10: §5 | B10: 수치카드 | C10: =COUNTIF(Captures!D:D,"§5") -> 0 | D10: 3 | E10: 4 | F10: =IF(C10=0,"미착수",IF(C10<D10,"부족 "&(D10-C10)&"건",IF(C10<=E10,"OK","초과"))) -> 미착수
A11: §6 | B11: 상품카드 | C11: =COUNTIF(Captures!D:D,"§6") -> 0 | D11: 3 | E11: 4 | F11: =IF(C11=0,"미착수",IF(C11<D11,"부족 "&(D11-C11)&"건",IF(C11<=E11,"OK","초과"))) -> 미착수
A12: §7 | B12: 로고월 | C12: =COUNTIF(Captures!D:D,"§7") -> 0 | D12: 3 | E12: 4 | F12: =IF(C12=0,"미착수",IF(C12<D12,"부족 "&(D12-C12)&"건",IF(C12<=E12,"OK","초과"))) -> 미착수
A13: §8 | B13: 스텝 | C13: =COUNTIF(Captures!D:D,"§8") -> 0 | D13: 3 | E13: 4 | F13: =IF(C13=0,"미착수",IF(C13<D13,"부족 "&(D13-C13)&"건",IF(C13<=E13,"OK","초과"))) -> 미착수
A14: §9 | B14: 상담사 | C14: =COUNTIF(Captures!D:D,"§9") -> 0 | D14: 2 | E14: 3 | F14: =IF(C14=0,"미착수",IF(C14<D14,"부족 "&(D14-C14)&"건",IF(C14<=E14,"OK","초과"))) -> 미착수
A15: §10 | B15: 통계 | C15: =COUNTIF(Captures!D:D,"§10") -> 0 | D15: 3 | E15: 3 | F15: =IF(C15=0,"미착수",IF(C15<D15,"부족 "&(D15-C15)&"건",IF(C15<=E15,"OK","초과"))) -> 미착수
A16: §11 | B16: 비교카드 | C16: =COUNTIF(Captures!D:D,"§11") -> 0 | D16: 3 | E16: 3 | F16: =IF(C16=0,"미착수",IF(C16<D16,"부족 "&(D16-C16)&"건",IF(C16<=E16,"OK","초과"))) -> 미착수
A17: §12 | B17: 페르소나 | C17: =COUNTIF(Captures!D:D,"§12") -> 0 | D17: 2 | E17: 3 | F17: =IF(C17=0,"미착수",IF(C17<D17,"부족 "&(D17-C17)&"건",IF(C17<=E17,"OK","초과"))) -> 미착수
A18: §13 | B18: FAQ | C18: =COUNTIF(Captures!D:D,"§13") -> 0 | D18: 3 | E18: 3 | F18: =IF(C18=0,"미착수",IF(C18<D18,"부족 "&(D18-C18)&"건",IF(C18<=E18,"OK","초과"))) -> 미착수
A19: §14 | B19: 후기 | C19: =COUNTIF(Captures!D:D,"§14") -> 0 | D19: 2 | E19: 3 | F19: =IF(C19=0,"미착수",IF(C19<D19,"부족 "&(D19-C19)&"건",IF(C19<=E19,"OK","초과"))) -> 미착수
A20: §15 | B20: StickyCTA | C20: =COUNTIF(Captures!D:D,"§15") -> 0 | D20: 3 | E20: 3 | F20: =IF(C20=0,"미착수",IF(C20<D20,"부족 "&(D20-C20)&"건",IF(C20<=E20,"OK","초과"))) -> 미착수
A21: §16 | B21: Footer | C21: =COUNTIF(Captures!D:D,"§16") -> 0 | D21: 3 | E21: 4 | F21: =IF(C21=0,"미착수",IF(C21<D21,"부족 "&(D21-C21)&"건",IF(C21<=E21,"OK","초과"))) -> 미착수
A22: 합계 | C22: =SUM(C6:C21) -> 0 | D22: =SUM(D6:D21) -> 48 | E22: =SUM(E6:E21) -> 58
A24: B. 브랜드 커버리지
A25: 브랜드 | B25: 군 | C25: 캡처 수
A26: 키움에셋플래너 | B26: A | C26: =COUNTIF(Captures!C:C,"키움에셋플래너") -> 0
A27: 메타리치 | B27: A | C27: =COUNTIF(Captures!C:C,"메타리치") -> 0
A28: 굿리치 | B28: A | C28: =COUNTIF(Captures!C:C,"굿리치") -> 0
A29: 보험다모아 | B29: A | C29: =COUNTIF(Captures!C:C,"보험다모아") -> 0
A30: 내보험찾아줌 | B30: A | C30: =COUNTIF(Captures!C:C,"내보험찾아줌") -> 0
A31: 보맵 | B31: A | C31: =COUNTIF(Captures!C:C,"보맵") -> 0
A32: 보험플러스 | B32: A | C32: =COUNTIF(Captures!C:C,"보험플러스") -> 0
A33: 토스인슈어런스 | B33: A | C33: =COUNTIF(Captures!C:C,"토스인슈어런스") -> 0
A34: 삼성화재 다이렉트 | B34: B | C34: =COUNTIF(Captures!C:C,"삼성화재 다이렉트") -> 0
A35: DB손해보험 | B35: B | C35: =COUNTIF(Captures!C:C,"DB손해보험") -> 0
A36: 현대해상 다이렉트 | B36: B | C36: =COUNTIF(Captures!C:C,"현대해상 다이렉트") -> 0
A37: 메리츠화재 다이렉트 | B37: B | C37: =COUNTIF(Captures!C:C,"메리츠화재 다이렉트") -> 0
A38: 캐롯손해보험 | B38: B | C38: =COUNTIF(Captures!C:C,"캐롯손해보험") -> 0
A39: KB손해보험 다이렉트 | B39: B | C39: =COUNTIF(Captures!C:C,"KB손해보험 다이렉트") -> 0
A40: 라이나생명 다이렉트 | B40: B | C40: =COUNTIF(Captures!C:C,"라이나생명 다이렉트") -> 0
A41: 토스 | B41: C | C41: =COUNTIF(Captures!C:C,"토스") -> 0
A42: 카카오페이 | B42: C | C42: =COUNTIF(Captures!C:C,"카카오페이") -> 0
...
